Workbook

Sheet Gesamtbewertung
A1: ="Bewertung "&B6 -> Bewertung CAS KI für Softwareentwicklung
A3: Name Verfasser, Verfasserin | B3: Verf. Vorname | C3: Verf. Nachname
A4: Titel der CAS-Arbeit
A5: Vertraulichkeitsstufe | B5: Öffentlich (auch elektronische bereitstellung möglich) Vertraulich (nur innerhalb der FHNW einsehbar) Geheim (unter Verschluss im Archiv, nicht einsehbar)
A6: Programm und Standort | B6: CAS KI für Softwareentwicklung | E6: Windisch
A7: Name Betreuer/in | B7: Vorname | C7: Nachname
A8: Name Programmleiter/in | B8: Samuel | C8: Fricker
A9: Ort, Datum | B9: Windisch | C9: 46265
C11: Note | D11: Gewicht
B13: schriftliche Arbeit | C13: ='Bewertung schriftliche Arbeit'!F39 -> 1 | D13: 0.8
B14: Präsentation | C14: ='Bewertung Präsentation'!F30 -> 1 | D14: 0.2
A15: Gesamtnote, nicht gerundet | C15: =ROUND((C13*D13)+(C14*D14),1) -> 1
A16: Gesamtnote, gerundet auf eine halbe Note | C16: =MROUND((C13*D13)+(C14*D14),0.5) -> 1
A18: Gesamtwürdigung der Arbeit (mind. 150 Wörter): Verständnis der Fragestellung, methodisches Vorgehen, Qualität der Literatur und Datenerhebung, Zusammenarbeit mit den Beteiligten, Kommunikation, Arbeitsweise, Einbezug von Feedbacks; Qualität, Nachvollziehbarkeit und Praxistauglichkeit des Ergebnisses, Relevanz des eigenen Beitrags, Zufriedenheit der Auftraggeberschaft; Qualität der Präsentation und Souveränität der Diskussion.
A21: Der Betreuer / die Betreuerin bestätigt, dass die Arbeit bezüglich Einhaltung akademischer Standards überprüft wurde.
A23: Ort, Datum | B23: Unterschrift Betreuer/in
A25: Ort, Datum | B25: Unterschrift Programmleiter/in

Sheet Bewertung schriftliche Arbeit
A1: =Gesamtbewertung!A1 -> Bewertung CAS KI für Softwareentwicklung | N1: Student 1 FN | O1: Student 1 LN | P1: Student 2 FN | Q1: Student 2 LN | R1: Student 3 FN | S1: Student 3 LN | T1: Student 4 FN | U1: Student 4 LN | V1: Student 5 FN | W1: Student 5 LN | X1: Student 6 FN | Y1: Student 6 LN | Z1: Lecturer FN | AA1: Lecturer LN | AB1: Co-Expert FN | AC1: Co-Expert LN | AD1: Type | AE1: Privacy | AF1: Title | AG1: Programme | AH1: Location | AI1: Company | AJ1: Trait Category | AK1: Trait | AL1: Text Rating | AM1: Number Rating | AN1: Objective No. | AO1: Grade written | AP1: Grade oral
N2: =[1]Gesamtbewertung!B3 -> #REF! | O2: =[1]Gesamtbewertung!C3 -> #REF! | Z2: =[1]Gesamtbewertung!B7 -> #REF! | AA2: =[1]Gesamtbewertung!C7 -> #REF! | AB2: =[1]Gesamtbewertung!B8 -> #REF! | AC2: =[1]Gesamtbewertung!C8 -> #REF! | AD2: =[1]Gesamtbewertung!#REF! -> #REF! | AE2: =[1]Gesamtbewertung!B5 -> #REF! | AF2: =[1]Gesamtbewertung!B4 -> 0 | AG2: =[1]Gesamtbewertung!B6 -> #REF! | AH2: =[1]Gesamtbewertung!E6 -> #REF! | AI2: =[1]Gesamtbewertung!#REF! -> #REF! | AJ2: =A9 -> 1. Zielformulierung, Theorie, Methode | AK2: =A9 -> 1. Zielformulierung, Theorie, Methode | AL2: =IF(F9=$C$8,$C9,IF(F9=$D$8,$D9,IF(F9=$E$8,$E9,""))) | AM2: =F9 -> 0.15 | AN2: =L9 -> 0 | AO2: =[1]Gesamtbewertung!$C$13 -> #REF!
A3: =Gesamtbewertung!A4 -> Titel der CAS-Arbeit | B3: =Gesamtbewertung!B4 -> 0 | AJ3: =A10 -> Ziele, Fragestellung und deren Abgrenzung | AK3: =A10 -> Ziele, Fragestellung und deren Abgrenzung | AL3: =IF(F10=$C$8,$C10,IF(F10=$D$8,$D10,IF(F10=$E$8,$E10,""))) | AM3: =F10 -> 0 | AN3: =L10 -> 2.1
A4: Name | B4: =Gesamtbewertung!B3 -> Verf. Vorname | D4: =Gesamtbewertung!C3 -> Verf. Nachname | AJ4: =A11 -> Aktualität und Repräsentativität der Quellen (Fachliteratur) aus Wissenschaft und Praxis | AK4: =A11 -> Aktualität und Repräsentativität der Quellen (Fachliteratur) aus Wissenschaft und Praxis | AL4: =IF(F11=$C$8,$C11,IF(F11=$D$8,$D11,IF(F11=$E$8,$E11,""))) | AM4: =F11 -> 0 | AN4: =L11 -> 3.1
AJ5: =A12 -> Verknüpfung der Quelleninhalte mit eigenen Gedanken / Kritische Reflexion | AK5: =A12 -> Verknüpfung der Quelleninhalte mit eigenen Gedanken / Kritische Reflexion | AL5: =IF(F12=$C$8,$C12,IF(F12=$D$8,$D12,IF(F12=$E$8,$E12,""))) | AM5: =F12 -> 0 | AN5: =L12 -> 3.1
A6: Bewertungskriterium | B6: Gewicht | C6: Exceeds expectations | D6: Meets expectations | E6: Does not meet expectations | F6: Bewertung | G6: Bemerkungen | I6: Faktor | J6: Maximal | K6: erreicht | L6: korrespondiert mit Objectives … | AJ6: =A13 -> Klärung und Verwendung der (Fach)-Begriffe | AK6: =A13 -> Klärung und Verwendung der (Fach)-Begriffe | AL6: =IF(F13=$C$8,$C13,IF(F13=$D$8,$D13,IF(F13=$E$8,$E13,""))) | AM6: =F13 -> 0 | AN6: =L13 -> 0
C7: 3 | D7: 2 | E7: 1 | G7: Punkte | AJ7: =A14 -> Passung der Methoden zur Fragestellung | AK7: =A14 -> Passung der Methoden zur Fragestellung | AL7: =IF(F14=$C$8,$C14,IF(F14=$D$8,$D14,IF(F14=$E$8,$E14,""))) | AM7: =F14 -> 0 | AN7: =L14 -> 2.1
C8: 5 | D8: 3.5 | E8: 2 | AJ8: =A15 -> 0 | AK8: =A15 -> 0 | AL8: =IF(F15=$C$8,$C15,IF(F15=$D$8,$D15,IF(F15=$E$8,$E15,""))) | AM8: =F15 -> 0 | AN8: =L15 -> 0
A9: 1. Zielformulierung, Theorie, Methode | F9: 0.15 | G9: =K9&" von" -> 0 von | H9: =J9 -> 25 | J9: =SUM(J10:J15) -> 25 | K9: =SUM(K10:K15) -> 0 | AJ9: =A16 -> 2. Vorgehensweise, Analyse, Lösungsentwicklung | AK9: =A16 -> 2. Vorgehensweise, Analyse, Lösungsentwicklung | AL9: =IF(F16=$C$8,$C16,IF(F16=$D$8,$D16,IF(F16=$E$8,$E16,""))) | AM9: =F16 -> 0.5 | AN9: =L16 -> 0
A10: Ziele, Fragestellung und deren Abgrenzung | B10: 1 | C10: Ziele bzw. Fragestellungen sind eindeutig, stimmig, vollständig formuliert und klar abgegrenzt | D10: Ziele bzw. Fragestellungen sind passend formuliert und weitgehend abgegrenzt | E10: Geeignete Ziele bzw. Fragestellungen fehlen teilweise oder sind unklar formuliert bzw. schlecht abgegrenzt | I10: =IF(F10=$C$7,$C$8,IF(F10=$D$7,$D$8,IF(F10=$E$7,$E$8,0))) -> 0 | J10: =B10*$C$8 -> 5 | K10: =B10*I10 -> 0 | L10: 2.1 | AJ10: =#REF! -> #REF! | AK10: =#REF! -> #REF! | AL10: =IF(#REF!=$C$8,#REF!,IF(#REF!=$D$8,#REF!,IF(#REF!=$E$8,#REF!,""))) -> #REF! | AM10: =#REF! -> #REF! | AN10: =#REF! -> #REF!
A11: Aktualität und Repräsentativität der Quellen (Fachliteratur) aus Wissenschaft und Praxis | B11: 1 | C11: Die verwendeten Quellen repräsentieren in jeder Hinsicht (qualitativ und quantitativ) den aktuellen Stand der Kenntnisse aus Wissenschaft und Praxis (Fachliteratur) | D11: Die verwendeten Quellen sind meistens aktuell und umfassend auf das Thema ausgerichtet. Recht guter Anteil an aktueller Fachliteratur und/oder gute Mischung von Büchern und Zeitschriftenartikeln | E11: Die verwendeten Quellen berücksichtigen die aktuelle Fachliteratur quantitativ und/oder qualitativ ungenügend | I11: =IF(F11=$C$7,$C$8,IF(F11=$D$7,$D$8,IF(F11=$E$7,$E$8,0))) -> 0 | J11: =B11*$C$8 -> 5 | K11: =B11*I11 -> 0 | L11: 3.1 | AJ11: =#REF! -> #REF! | AK11: =#REF! -> #REF! | AL11: =IF(#REF!=$C$8,#REF!,IF(#REF!=$D$8,#REF!,IF(#REF!=$E$8,#REF!,""))) -> #REF! | AM11: =#REF! -> #REF! | AN11: =#REF! -> #REF!
A12: Verknüpfung der Quelleninhalte mit eigenen Gedanken / Kritische Reflexion | B12: 1 | C12: Die Inhalte der verwendeten Quellen sind sehr gut und häufig mit den eigenen Gedanken verknüpft. Eine kritische Auseinandersetzung findet statt | D12: Die Inhalte der verwendeten Quellen sind teilweise mit den eigenen Gedanken verbunden (z.B. in Form von Zusammenfassungen). Eine kritische Auseinandersetzung mit den Quellen dürfte noch umfassender sein | E12: Die Quelleninhalte werden zu wenig reflektiert bzw. ohne ausreichende kritische Auseinandersetzung mit den Inhalten übernommen. Sie wirken dadurch isoliert. | I12: =IF(F12=$C$7,$C$8,IF(F12=$D$7,$D$8,IF(F12=$E$7,$E$8,0))) -> 0 | J12: =B12*$C$8 -> 5 | K12: =B12*I12 -> 0 | L12: 3.1 | AJ12: =#REF! -> #REF! | AK12: =#REF! -> #REF! | AL12: =IF(#REF!=$C$8,#REF!,IF(#REF!=$D$8,#REF!,IF(#REF!=$E$8,#REF!,""))) -> #REF! | AM12: =#REF! -> #REF! | AN12: =#REF! -> #REF!
A13: Klärung und Verwendung der (Fach)-Begriffe | B13: 1 | C13: Alle wesentlichen (Fach)-Begriffe sind präzise geklärt und absolut adäquat verwendet | D13: Die meisten wesentlichen(Fach-) Begriffe sind geklärt und richtig verwendet | E13: Fachbegriffe werden nicht ausreichend diskutiert und bleiben daher z.T. ungeklärt. Die wesentliche Fachterminologie fehlt | I13: =IF(F13=$C$7,$C$8,IF(F13=$D$7,$D$8,IF(F13=$E$7,$E$8,0))) -> 0 | J13: =B13*$C$8 -> 5 | K13: =B13*I13 -> 0 | AJ13: =A23 -> Berücksichtigung von Nachhaltigkeit | AK13: =A23 -> Berücksichtigung von Nachhaltigkeit | AL13: =IF(F23=$C$8,$C23,IF(F23=$D$8,$D23,IF(F23=$E$8,$E23,""))) | AM13: =F23 -> 0 | AN13: =L23 -> 3.1
A14: Passung der Methoden zur Fragestellung | B14: 1 | C14: Methodische Ansätze sind optimal auf die Fragestellung ausgerichtet | D14: Methodische Ansätze passen zur Fragestellung | E14: Methodische Ansätze werden der Fragestellung nicht im geforderten Mass gerecht | I14: =IF(F14=$C$7,$C$8,IF(F14=$D$7,$D$8,IF(F14=$E$7,$E$8,0))) -> 0 | J14: =B14*$C$8 -> 5 | K14: =B14*I14 -> 0 | L14: 2.1 | AJ14: =#REF! -> #REF! | AK14: =#REF! -> #REF! | AL14: =IF(#REF!=$C$8,#REF!,IF(#REF!=$D$8,#REF!,IF(#REF!=$E$8,#REF!,""))) -> #REF! | AM14: =#REF! -> #REF! | AN14: =#REF! -> #REF!
I15: =IF(F15=$C$7,$C$8,IF(F15=$D$7,$D$8,IF(F15=$E$7,$E$8,0))) -> 0 | J15: =B15*$C$8 -> 0 | K15: =B15*I15 -> 0 | AJ15: =#REF! -> #REF! | AK15: =#REF! -> #REF! | AL15: =IF(#REF!=$C$8,#REF!,IF(#REF!=$D$8,#REF!,IF(#REF!=$E$8,#REF!,""))) -> #REF! | AM15: =#REF! -> #REF! | AN15: =#REF! -> #REF!
A16: 2. Vorgehensweise, Analyse, Lösungsentwicklung | F16: 0.5 | G16: =K16&" von" -> 0 von | H16: =J16 -> 35 | J16: =SUM(J17:J23) -> 35 | K16: =SUM(K17:K23) -> 0 | AJ16: =A24 -> 0 | AK16: =A24 -> 0 | AL16: =IF(F24=$C$8,$C24,IF(F24=$D$8,$D24,IF(F24=$E$8,$E24,""))) | AM16: =F24 -> 0 | AN16: =L24 -> 0
A17: Ziele - Einbettung der Ziele in Bezug auf Strategie und Unternehmensziele | B17: 1 | C17: Wurde sehr gut umgesetzt und hat nur einzelne wenige Verbesserungsmöglichkeiten. | D17: Wurde im Wesentlichen gut umgesetzt, kann aber noch verbessert werden. | E17: Das Konzept wurde nicht verstanden oder wurde in der Arbeit nicht berücksichtigt oder weggelassen. | I17: =IF(F17=$C$7,$C$8,IF(F17=$D$7,$D$8,IF(F17=$E$7,$E$8,0))) -> 0 | J17: =B17*$C$8 -> 5 | K17: =B17*I17 -> 0 | L17: 1.1
A18: Auswahl des KI-basierten Ansatzes | B18: 1 | C18: Wurde sehr gut umgesetzt und hat nur einzelne wenige Verbesserungsmöglichkeiten. | D18: Wurde im Wesentlichen gut umgesetzt, kann aber noch verbessert werden. | E18: Das Konzept wurde nicht verstanden oder wurde in der Arbeit nicht berücksichtigt oder weggelassen. | I18: =IF(F18=$C$7,$C$8,IF(F18=$D$7,$D$8,IF(F18=$E$7,$E$8,0))) -> 0 | J18: =B18*$C$8 -> 5 | K18: =B18*I18 -> 0 | L18: 1.1
A19: Integration des KI-basierten Ansatzes in Unternehmenskontext | B19: 1 | C19: Wurde sehr gut umgesetzt und hat nur einzelne wenige Verbesserungsmöglichkeiten. | D19: Wurde im Wesentlichen gut umgesetzt, kann aber noch verbessert werden. | E19: Das Konzept wurde nicht verstanden oder wurde in der Arbeit nicht berücksichtigt oder weggelassen. | I19: =IF(F19=$C$7,$C$8,IF(F19=$D$7,$D$8,IF(F19=$E$7,$E$8,0))) -> 0 | J19: =B19*$C$8 -> 5 | K19: =B19*I19 -> 0 | L19: 1.1
A20: Umsetzung des KI-basierten Ansatzes | B20: 1 | C20: Wurde sehr gut umgesetzt und hat nur einzelne wenige Verbesserungsmöglichkeiten. | D20: Wurde im Wesentlichen gut umgesetzt, kann aber noch verbessert werden. | E20: Das Konzept wurde nicht verstanden oder wurde in der Arbeit nicht berücksichtigt oder weggelassen. | I20: =IF(F20=$C$7,$C$8,IF(F20=$D$7,$D$8,IF(F20=$E$7,$E$8,0))) -> 0 | J20: =B20*$C$8 -> 5 | K20: =B20*I20 -> 0 | L20: 1.2
A21: Validierung der KI-basierten Ansatzes | B21: 1 | C21: Wurde sehr gut umgesetzt und hat nur einzelne wenige Verbesserungsmöglichkeiten. | D21: Wurde im Wesentlichen gut umgesetzt, kann aber noch verbessert werden. | E21: Das Konzept wurde nicht verstanden oder wurde in der Arbeit nicht berücksichtigt oder weggelassen. | I21: =IF(F21=$C$7,$C$8,IF(F21=$D$7,$D$8,IF(F21=$E$7,$E$8,0))) -> 0 | J21: =B21*$C$8 -> 5 | K21: =B21*I21 -> 0 | L21: 1.2
A22: Berücksichtigung von Ethik und Gesetzen | B22: 1 | C22: Wurde sehr gut umgesetzt und hat nur einzelne wenige Verbesserungsmöglichkeiten. | D22: Wurde im Wesentlichen gut umgesetzt, kann aber noch verbessert werden. | E22: Das Konzept wurde nicht verstanden oder wurde in der Arbeit nicht berücksichtigt oder weggelassen. | I22: =IF(F22=$C$7,$C$8,IF(F22=$D$7,$D$8,IF(F22=$E$7,$E$8,0))) -> 0 | J22: =B22*$C$8 -> 5 | K22: =B22*I22 -> 0 | L22: 2.2
A23: Berücksichtigung von Nachhaltigkeit | B23: 1 | C23: Wurde sehr gut umgesetzt und hat nur einzelne wenige Verbesserungsmöglichkeiten. | D23: Wurde im Wesentlichen gut umgesetzt, kann aber noch verbessert werden. | E23: Das Konzept wurde nicht verstanden oder wurde in der Arbeit nicht berücksichtigt oder weggelassen. | I23: =IF(F23=$C$7,$C$8,IF(F23=$D$7,$D$8,IF(F23=$E$7,$E$8,0))) -> 0 | J23: =B23*$C$8 -> 5 | K23: =B23*I23 -> 0 | L23: 3.1 | AJ23: =A28 -> Klarheit und Signifikanz der eigenen Beiträge | AK23: =A28 -> Klarheit und Signifikanz der eigenen Beiträge | AL23: =IF(F28=$C$8,$C28,IF(F28=$D$8,$D28,IF(F28=$E$8,$E28,""))) | AM23: =F28 -> 0 | AN23: =L28 -> 0
I24: =IF(F24=$C$7,$C$8,IF(F24=$D$7,$D$8,IF(F24=$E$7,$E$8,0))) -> 0 | J24: =B24*$C$8 -> 0 | K24: =B24*I24 -> 0 | AJ24: =A30 -> Management bzw. Executive Summary | AK24: =A30 -> Management bzw. Executive Summary | AL24: =IF(F30=$C$8,$C30,IF(F30=$D$8,$D30,IF(F30=$E$8,$E30,""))) | AM24: =F30 -> 0 | AN24: =L30 -> 0
A25: 3. Zielerreichung, Gehalt der Ergebnisse | F25: 0.2 | G25: =K25&" von" -> 0 von | H25: =J25 -> 30 | J25: =SUM(J26:J32) -> 30 | K25: =SUM(K26:K32) -> 0 | AJ25: =A31 -> Fazit (Zusammenfassung und Empfehlung) | AK25: =A31 -> Fazit (Zusammenfassung und Empfehlung) | AL25: =IF(F31=$C$8,$C31,IF(F31=$D$8,$D31,IF(F31=$E$8,$E31,""))) | AM25: =F31 -> 0 | AN25: =L31 -> 0
A26: Beantwortung der Fragestellung und Erreichung der vereinbarten Ziele | B26: 1 | C26: Die Kernfragestellung wird in ausgezeichneter Weise angegangen und beantwortet. Die vereinbarten Ziele sind übertroffen | D26: Die Kernfragestellung wird adressiert und grundsätzlich beantwortet. Die vereinbarten Ziele sind erreicht | E26: Die Kernfragestellung wird höchstens knapp genügend beantwortet und die vereinbarten Ziele sind nur teilweise erreicht | I26: =IF(F26=$C$7,$C$8,IF(F26=$D$7,$D$8,IF(F26=$E$7,$E$8,0))) -> 0 | J26: =B26*$C$8 -> 5 | K26: =B26*I26 -> 0 | AJ26: =A32 -> 0 | AK26: =A32 -> 0 | AL26: =IF(F32=$C$8,$C32,IF(F32=$D$8,$D32,IF(F32=$E$8,$E32,""))) | AM26: =F32 -> 0 | AN26: =L32 -> 0
A27: Qualität der Ergebnisse und Empfehlungen | B27: 1 | C27: Das Ergebnis ist vollständig, abgerundet und in jeder Hinsicht nachvollziehbar. Sehr treffende Empfehlungen | D27: Das Ergebnis ist weitgehend vollständig und in der Regel gut nachvollziehbar. Solide Empfehlungen | E27: Dem Ergebnis fehlen Elemente und/oder es ist nicht immer ausreichend nachvollziehbar. Teilweise unbefriedigende Empfehlungen | I27: =IF(F27=$C$7,$C$8,IF(F27=$D$7,$D$8,IF(F27=$E$7,$E$8,0))) -> 0 | J27: =B27*$C$8 -> 5 | K27: =B27*I27 -> 0 | L27: 3.1 | AJ27: =A33 -> 4. Dokumentation, formale Vorgaben | AK27: =A33 -> 4. Dokumentation, formale Vorgaben | AL27: =IF(F33=$C$8,$C33,IF(F33=$D$8,$D33,IF(F33=$E$8,$E33,""))) | AM27: =F33 -> 0.15 | AN27: =L33 -> 0
A28: Klarheit und Signifikanz der eigenen Beiträge | B28: 1 | C28: Der eigene Beitrag ist signifikant und in der Arbeit permanent erkennbar | D28: Der eigene Beitrag ist relevant und gut erkennbar | E28: Der eigene Beitrag ist nicht oder kaum erkennbar | I28: =IF(F28=$C$7,$C$8,IF(F28=$D$7,$D$8,IF(F28=$E$7,$E$8,0))) -> 0 | J28: =B28*$C$8 -> 5 | K28: =B28*I28 -> 0 | AJ28: =A34 -> Aufbau gemäss Vorgaben (Vollständigkeit und Struktur, Länge, Zitate, Literaturverzeichnis, etc.) | AK28: =A34 -> Aufbau gemäss Vorgaben (Vollständigkeit und Struktur, Länge, Zitate, Literaturverzeichnis, etc.) | AL28: =IF(F34=$C$8,$C34,IF(F34=$D$8,$D34,IF(F34=$E$8,$E34,""))) | AM28: =F34 -> 0 | AN28: =L34 -> 0
A29: Transferierbarkeit (Übertragbarkeit) der Ergebnisse auf andere Unternehmen | B29: 1 | C29: Die Ergebnisse und Empfehlungen sind von allgemeiner Gültigkeit und lassen sich sehr gut und gewinnbringend auf andere Unternehmungen übertragen | D29: Die Ergebnisse und Empfehlungen lassen sich zu einem guten Teil auf andere Unternehmungen in ähnlicher oder gleicher Ausgangslage übertragen | E29: Die Behandlung der Problemstellung lässt nur eine isolierte Betrachtungsweise zu und ist nicht auf andere Unternehmungen übertragbar | I29: =IF(F29=$C$7,$C$8,IF(F29=$D$7,$D$8,IF(F29=$E$7,$E$8,0))) -> 0 | J29: =B29*$C$8 -> 5 | K29: =B29*I29 -> 0 | AJ29: =A36 -> Erscheinungsbild (Layout, Grafiken, Schriftbild, Umbrüche, Titelseite etc.) | AK29: =A36 -> Erscheinungsbild (Layout, Grafiken, Schriftbild, Umbrüche, Titelseite etc.) | AL29: =IF(F36=$C$8,$C36,IF(F36=$D$8,$D36,IF(F36=$E$8,$E36,""))) | AM29: =F36 -> 0 | AN29: =L36 -> 0
A30: Management bzw. Executive Summary | B30: 1 | C30: Das Executive Summary liefert einer nicht involvierten Fachperson eine prägnante, aussagekräftige und vollständige Information über Ausgangslage, Ziel, Vorgehen und Ergebnisse der Arbeit | D30: Das Executive Summary enthält einige wenige Lücken, gibt einer nicht involvierten Fachperson jedoch einen genügenden Überblick über Ausgangslage, Ziel, Vorgehen und Ergebnisse der Arbeit | E30: Das Executive Summary ist lückenhaft, bzw. fehlerhaft und liefert einer nicht involvierten Fachperson einen ungenügenden Einblick in Ausgangslage, Ziel, Vorgehen und Ergebnisse der Arbeit. | I30: =IF(F30=$C$7,$C$8,IF(F30=$D$7,$D$8,IF(F30=$E$7,$E$8,0))) -> 0 | J30: =B30*$C$8 -> 5 | K30: =B30*I30 -> 0 | AJ30: =A37 -> 0 | AK30: =A37 -> 0 | AL30: =IF(F37=$C$8,$C37,IF(F37=$D$8,$D37,IF(F37=$E$8,$E37,""))) | AM30: =F37 -> 0 | AN30: =L37 -> 0
A31: Fazit (Zusammenfassung und Empfehlung) | B31: 1 | C31: Das Fazit ist vollständig, prägnant und zielführend, und die Empfehlungen sind qualitativ hochstehend und jederzeit passend | D31: Das Fazit enthält viele, wenn auch nicht alle Aspekte der Fragestellung, und die Empfehlungen sind gut jedoch nicht immer realistisch | E31: Das Fazit ist ungenügend bzw. die Empfehlungen sind mangelhaft oder ungeeignet | I31: =IF(F31=$C$7,$C$8,IF(F31=$D$7,$D$8,IF(F31=$E$7,$E$8,0))) -> 0 | J31: =B31*$C$8 -> 5 | K31: =B31*I31 -> 0 | AJ31: =A38 -> Schriftliche Kommunikation | AK31: =A38 -> Schriftliche Kommunikation | AL31: =IF(F38=$C$8,$C38,IF(F38=$D$8,$D38,IF(F38=$E$8,$E38,""))) | AM31: =F38 -> 1 | AN31: =L38 -> 0
I32: =IF(F32=$C$7,$C$8,IF(F32=$D$7,$D$8,IF(F32=$E$7,$E$8,0))) -> 0 | J32: =B32*$C$8 -> 0 | K32: =B32*I32 -> 0 | AJ32: =A39 -> Schriftliche Kommunikation | AK32: =A39 -> Schriftliche Kommunikation | AL32: =IF(F39=$C$8,$C39,IF(F39=$D$8,$D39,IF(F39=$E$8,$E39,""))) | AM32: =F39 -> 1 | AN32: =L39 -> 0
A33: 4. Dokumentation, formale Vorgaben | F33: 0.15 | G33: =K33&" von" -> 0 von | H33: =J33 -> 15 | J33: =SUM(J34:J37) -> 15 | K33: =SUM(K34:K37) -> 0 | AJ33: =A40 -> Der Dozent / die Dozentin hat die Arbeit bezüglich Einhaltung akademischer Standards überprüft. | AK33: =A40 -> Der Dozent / die Dozentin hat die Arbeit bezüglich Einhaltung akademischer Standards überprüft. | AL33: =IF(F40=$C$8,$C40,IF(F40=$D$8,$D40,IF(F40=$E$8,$E40,""))) | AM33: =F40 -> 0 | AN33: =L40 -> 0
A34: Aufbau gemäss Vorgaben (Vollständigkeit und Struktur, Länge, Zitate, Literaturverzeichnis, etc.) | B34: 1 | C34: Die Arbeit ist ausgezeichnet und nachvollziehbar aufgebaut, enthält alle notwendigen Teile und entspricht den Vorgaben in jeder Hinsicht | D34: Die Arbeit ist gut und nachvollziehbar aufgebaut. Es fehlen höchstens Kleinigkeiten, und den Vorgaben wird in der Regel entsprochen | E34: Die Arbeit ist mangelhaft und/oder unübersichtlich aufgebaut. Eventuell fehlen notwendige Teile. Vorgaben werden nicht oder in ungenügender Weise eingehalten | I34: =IF(F34=$C$7,$C$8,IF(F34=$D$7,$D$8,IF(F34=$E$7,$E$8,0))) -> 0 | J34: =B34*$C$8 -> 5 | K34: =B34*I34 -> 0 | AJ34: =A41 -> 0 | AK34: =A41 -> 0 | AL34: =IF(F41=$C$8,$C41,IF(F41=$D$8,$D41,IF(F41=$E$8,$E41,""))) | AM34: =F41 -> 0 | AN34: =L41 -> 0
A35: Grammatik, Orthographie, Schreibstil, Geschlechtsneutralität | B35: 1 | C35: Der Text ist in jeder verlangten Hinsicht, d.h. grammatikalisch, orthographisch, stilistisch einwandfrei, sowie geschlechterspezifisch korrekt | D35: Der Text ist mit wenigen Ausnahmen grammatikalisch, orthographisch und stilistisch korrekt. Die Arbeit ist grundsätzlich verständlich und enthält nur wenige geschlechterspezifischen Fehler | E35: Der Text ist mangelhaft redigiert und teilweise nicht gut verständlich. Er enthält viele grammatikalische, orthographische und/oder stilistische Fehler. Die gendergerechte Sprache wird nicht ausreichend beachtet | I35: =IF(F35=$C$7,$C$8,IF(F35=$D$7,$D$8,IF(F35=$E$7,$E$8,0))) -> 0 | J35: =B35*$C$8 -> 5 | K35: =B35*I35 -> 0 | AJ35: =A42 -> 0 | AK35: =A42 -> 0 | AL35: =IF(F42=$C$8,$C42,IF(F42=$D$8,$D42,IF(F42=$E$8,$E42,""))) | AM35: =F42 -> 0 | AN35: =L42 -> 0
A36: Erscheinungsbild (Layout, Grafiken, Schriftbild, Umbrüche, Titelseite etc.) | B36: 1 | C36: Das allgemeine Erscheinungsbild ist in jeder Beziehung attraktiv. Die Darstellungsmittel sind dem Gegenstand jederzeit angemessen (Text, Photo, Grafik) | D36: Das allgemeine Erscheinungsbild ist in Ordnung (= lesbar, verständlich, übersichtlich). Die Darstellungsmittel werden in der Regel angemessen eingesetzt (Text, Photo, Grafik) | E36: Das allgemeine Erscheinungsbild ist wenig attraktiv (nicht immer lesbar, gelegentlich unverständlich und nicht übersichtlich). Die Darstellungsmittel sind dem Gegenstand nicht angemessen (Text, Photo, Grafik) | I36: =IF(F36=$C$7,$C$8,IF(F36=$D$7,$D$8,IF(F36=$E$7,$E$8,0))) -> 0 | J36: =B36*$C$8 -> 5 | K36: =B36*I36 -> 0 | AJ36: =A43 -> 0 | AK36: =A43 -> 0 | AL36: =IF(F43=$C$8,$C43,IF(F43=$D$8,$D43,IF(F43=$E$8,$E43,""))) | AM36: =F43 -> 0 | AN36: =L43 -> 0
I37: =IF(F37=$C$7,$C$8,IF(F37=$D$7,$D$8,IF(F37=$E$7,$E$8,0))) -> 0 | J37: =B37*$C$8 -> 0 | K37: =B37*I37 -> 0 | AJ37: =A44 -> 0 | AK37: =A44 -> 0 | AL37: =IF(F44=$C$8,$C44,IF(F44=$D$8,$D44,IF(F44=$E$8,$E44,""))) | AM37: =F44 -> 0 | AN37: =L44 -> 0
A38: Schriftliche Kommunikation | C38: Notenvorschlag | F38: =(5*K39)+1 -> 1 | J38: =SUM(J33,J25,J16,J9) -> 105 | K38: =SUM(K33,K25,K16,K9) -> 0 | AJ38: =A45 -> 0 | AK38: =A45 -> 0 | AL38: =IF(F45=$C$8,$C45,IF(F45=$D$8,$D45,IF(F45=$E$8,$E45,""))) | AM38: =F45 -> 0 | AN38: =L45 -> 0
A39: Schriftliche Kommunikation | C39: Gesetzte Note (kann überschrieben werden) | F39: =F38 -> 1 | I39: gewichtet: | K39: =SUM($K$33/$J$33*$F$33,$K$25/$J$25*$F$25,$K$16/$J$16*$F$16,$K$9/$J$9*$F$9) -> 0 | AJ39: =A46 -> 0 | AK39: =A46 -> 0 | AL39: =IF(F46=$C$8,$C46,IF(F46=$D$8,$D46,IF(F46=$E$8,$E46,""))) | AM39: =F46 -> 0 | AN39: =L46 -> 0
A40: Der Dozent / die Dozentin hat die Arbeit bezüglich Einhaltung akademischer Standards überprüft. | AJ40: =A47 -> 0 | AK40: =A47 -> 0 | AL40: =IF(F47=$C$8,$C47,IF(F47=$D$8,$D47,IF(F47=$E$8,$E47,""))) | AM40: =F47 -> 0 | AN40: =L47 -> 0
...

Sheet Bewertung Präsentation
A1: =Gesamtbewertung!A1&" (mündlich)" -> Bewertung CAS KI für Softwareentwicklung (mündlich)
A3: =Gesamtbewertung!A4 -> Titel der CAS-Arbeit | B3: =Gesamtbewertung!B4 -> 0
A4: Name | B4: =Gesamtbewertung!B3 -> Verf. Vorname | D4: =Gesamtbewertung!C3 -> Verf. Nachname
A6: Datum der Präsentation
A8: Bewertungskriterium | B8: Gewicht | C8: Exceeds expectations | D8: Meets expectations | E8: Does not meet expectations | F8: Bewertung | G8: Bemerkungen | I8: Faktor | J8: Maximal | K8: erreicht | L8: korrespondiert mit Objectives …
C9: 3 | D9: 2 | E9: 1 | G9: Punkte
C10: 5 | D10: 3.5 | E10: 2
A11: 1. Auftrittskompetenz | F11: 0.2 | G11: =K11&" von" -> 0 von | H11: =J11 -> 45 | J11: =SUM(J12:J17) -> 45 | K11: =SUM(K12:K17) -> 0
A12: Freier Vortrag | B12: 2 | C12: Der Vortrag wird durchgängig in freier Rede gehalten und wirkt sehr souverän | D12: Der Vortrag wird sicher, aber nicht konsequent in freier Rede gehalten (gelegentliches Ablesen) | E12: Beim Vortrag wird mehrheitlich abgelesen | I12: =IF(F12=$C$9,$C$10,IF(F12=$D$9,$D$10,IF(F12=$E$9,$E$10,0))) -> 0 | J12: =B12*$C$10 -> 10 | K12: =I12*B12 -> 0 | L12: 3.2
A13: Sprache, Sprechtempo Sprechweise | B13: 2 | C13: Der Vortrag ist sprachlich ausgezeichnet, jederzeit verständlich und in optimalem Tempo vorgetragen | D13: Der Vortrag ist gut und ohne sprachbezogene Schwächen. Er ist sprachlich meistens deutlich und in angepasstem Tempo vorgetragen | E13: Der Vortrag enthält sprach- bezogene Schwächen, es mangelt an Sicherheit und Verständlichkeit. Deutlichkeit und korrektes Tempo sind nicht immer gegeben | I13: =IF(F13=$C$9,$C$10,IF(F13=$D$9,$D$10,IF(F13=$E$9,$E$10,0))) -> 0 | J13: =B13*$C$10 -> 10 | K13: =I13*B13 -> 0
A14: Blickkontakt, Gestik, Körperhaltung | B14: 2 | C14: Der Blickkontakt zum Publikum wird permanent hergestellt, die Körperhaltung ist offen und gelöst | D14: Der Blickkontakt zum Publikum ist nicht immer vorhanden, die Körperhaltung ist gelegentlich verkrampft | E14: Der Blickkontakt zum Publikum wird vermieden, die Körperhaltung ist öfters verkrampft | I14: =IF(F14=$C$9,$C$10,IF(F14=$D$9,$D$10,IF(F14=$E$9,$E$10,0))) -> 0 | J14: =B14*$C$10 -> 10 | K14: =I14*B14 -> 0
A15: Begeisterungsfähigkeit | B15: 2 | C15: Die Zuhörerschaft ist sehr angetan. Es entstand eine gute Beziehung zum Publikum | D15: Die Zuhörerschaft ist zufrieden. Es konnte teilweise eine Beziehung zum Publikum hergestellt werden | E15: Die Zuhörerschaft ist enttäuscht. Der Vortragende findet keinen Draht zum Publikum | I15: =IF(F15=$C$9,$C$10,IF(F15=$D$9,$D$10,IF(F15=$E$9,$E$10,0))) -> 0 | J15: =B15*$C$10 -> 10 | K15: =I15*B15 -> 0 | L15: 3.2
A16: Zeitmanagement | B16: 1 | C16: Die vorgegebene Vortragszeit wird im vorgegebenen Rahmen (25-30 Minuten) eingehalten | D16: Die vorgegebene Vortragszeit wird mit max. 1 Minute unter- oder überschritten (24 resp. 31) | E16: Die vorgegebene Vortragszeit wird mit über 1 Minute unter- oder überschritten (unter 24 oder über 31 Minuten) | I16: =IF(F16=$C$9,$C$10,IF(F16=$D$9,$D$10,IF(F16=$E$9,$E$10,0))) -> 0 | J16: =B16*$C$10 -> 5 | K16: =I16*B16 -> 0
A18: 2. Gestaltung und Verwendung der Medien | F18: 0.2 | G18: =K18&" von" -> 0 von | H18: =J18 -> 20 | J18: =SUM(J19:J21) -> 20 | K18: =SUM(K19:K21) -> 0
A19: Visualisierung | B19: 2 | C19: Einheitliches Folienlayout mit gutem Farbeinsatz, Textmenge/-information je Folie sehr ausgewogen, Schaubilder und Tabelleneinsatz vorbildlich. Ausgezeichnete Lesbarkeit der Folien. Sehr gute Abstimmung der Darstellungsmittel | D19: Einheitliches Folienlayout ok, Farbeinsatz teilweise nicht optimal. Textmenge/-information je Folie und Schaubilder/Tabelleneinsatz grundsätzlich ok. Lesbarkeit in der Regel gegeben. Grundsätzlich gute Abstimmung der Darstellungsmittel | E19: Kein einheitliches Folienlayout, u.U. unangemessener Farbeinsatz, Textmenge / -information je Folie ok, Schaubilder und/oder Tabelleneinsatz teilweise mangelhaft. Eingeschränkte Lesbarkeit und/oder inadäquate Abstimmung der Darstellungsmittel | I19: =IF(F19=$C$9,$C$10,IF(F19=$D$9,$D$10,IF(F19=$E$9,$E$10,0))) -> 0 | J19: =B19*$C$10 -> 10 | K19: =I19*B19 -> 0
A20: Medieneinsatz und -bedienung | B20: 2 | C20: Die Medien sind kompetent eingesetzt und sehr gut auf den Inhalt abgestimmt. Die Inhalte sind anschaulich dargestellt. Überzeugender Einsatz von Technik und mehreren Medien. Medienwechsel funktionieren reibungslos | D20: Die Medien sind auf den Inhalt abgestimmt und meist passend eingesetzt. Die Inhalte sind in der Regel anschaulich dargestellt. Keine Probleme bei der Bedienung der Technik, ist mit den Funktionen vertraut. Es wird aber nur ein Medium eingesetzt | E20: Die Medien sind ungeschickt eingesetzt, die Inhalte werden zu wenig anschaulich vermittelt. Die Technik ist nicht immer im Griff, es gibt Pannen. Es wird nur ein Medium eingesetzt | I20: =IF(F20=$C$9,$C$10,IF(F20=$D$9,$D$10,IF(F20=$E$9,$E$10,0))) -> 0 | J20: =B20*$C$10 -> 10 | K20: =I20*B20 -> 0
A22: 3. Inhalt der Präsentation | F22: 0.6 | G22: =K22&" von" -> 0 von | H22: =J22 -> 50 | J22: =SUM(J23:J28) -> 50 | K22: =SUM(K23:K28) -> 0
A23: Gliederung und Struktur | B23: 2 | C23: Die Präsentation ist durchgehend sehr gut strukturiert und in jeder Hinsicht übersichtlich | D23: Die Präsentation ist recht gut strukturiert und weitgehend übersichtlich | E23: Die Präsentation ist zu wenig gegliedert und insgesamt unübersichtlich. | I23: =IF(F23=$C$9,$C$10,IF(F23=$D$9,$D$10,IF(F23=$E$9,$E$10,0))) -> 0 | J23: =B23*$C$10 -> 10 | K23: =I23*B23 -> 0
A24: Vollständigkeit und sachliche Richtigkeit der Inhalte | B24: 2 | C24: Alle relevanten Inhalte werden mit allen wichtigen Aspekten korrekt dargestellt | D24: Die relevanten Inhalte sind fast alle vorhanden und korrekt dargestellt. Evtl. fehlen einige Aspekte | E24: Die relevanten Inhalte werden unvollständig oder fehlerhaft dargestellt bzw. es fehlen wichtige Aspekte. | I24: =IF(F24=$C$9,$C$10,IF(F24=$D$9,$D$10,IF(F24=$E$9,$E$10,0))) -> 0 | J24: =B24*$C$10 -> 10 | K24: =I24*B24 -> 0 | L24: 3.2
A25: Zusammenfassung und Fazit | B25: 1 | C25: Das Fazit ist vollständig, prägnant und zielführend, die Empfehlungen hochstehend und jederzeit passend | D25: Das Fazit enthält nicht alle Aspekte der Fragestellung. Die Empfehlungen sind nicht immer realistisch | E25: Das Fazit ist ungenügend und/oder die Empfehlungen sind mangelhaft oder ungeeignet | I25: =IF(F25=$C$9,$C$10,IF(F25=$D$9,$D$10,IF(F25=$E$9,$E$10,0))) -> 0 | J25: =B25*$C$10 -> 5 | K25: =I25*B25 -> 0 | L25: 3.2
A26: Diskussion, Nach-/ Verständnisfragen | B26: 4 | C26: Es wird souverän, korrekt und auf die Fragen fokussiert geantwortet. Es ist transparent, dass der Studierende die Materie und die Diskussion sehr gut im Griff hat | D26: Grundsätzlich ist der Studierende in der Lage, die Fragen gut und kompetent zu beantworten. Es kommt vor, dass ausweichend oder nicht immer korrekt geantwortet wird | E26: Es werden Fragen ungenügend oder sogar falsch beantwortet. Es werden nicht alle Fragen verstanden und/oder es bestehen Wissenslücken | I26: =IF(F26=$C$9,$C$10,IF(F26=$D$9,$D$10,IF(F26=$E$9,$E$10,0))) -> 0 | J26: =B26*$C$10 -> 20 | K26: =I26*B26 -> 0
A27: Ausblick | B27: 1 | C27: Erste Empfehlungen sind in der Umsetzung oder sind bereits realisiert. Weitere sollen gemäss Planung bald folgen. | D27: Konkrete Pläne und Absichten zur Umsetzung der Empfehlungen existieren und werden konkret angegangen | E27: Es besteht weder ein Plan noch können Aussagen zur Weiterverwendung der Resultate bzw. zur Befolgung der Empfehlungen gemacht werden | I27: =IF(F27=$C$9,$C$10,IF(F27=$D$9,$D$10,IF(F27=$E$9,$E$10,0))) -> 0 | J27: =B27*$C$10 -> 5 | K27: =I27*B27 -> 0
A29: Mündliche Kommunikation | C29: Errechnete Note | F29: =(5*K30)+1 -> 1 | J29: =SUM(J22,J18,J11) -> 115 | K29: =SUM(K22,K18,K11) -> 0
A30: Mündliche Kommunikation | C30: Gesetzte Note (kann überschrieben werden) | F30: =F29 -> 1 | I30: Gewichtet | K30: =SUM($K$22/$J$22*$F$22,$K$18/$J$18*$F$18,$K$11/$J$11*$F$11) -> 0
